<robot
  name="drchubo_v2">
  <link
    name="Body_Torso">
    <inertial>
      <origin
        xyz="0.00186303110078396 -0.000700932863027737 0.144864941081362"
        rpy="0 0 0" />
      <mass
        value="8.95351612283643" />
      <inertia
        ixx="0.097115701663788"
        ixy="-0.000131502652256357"
        ixz="-0.000536351319855448"
        iyy="0.0782182891825729"
        iyz="0.000190893230363873"
        izz="0.102805257612153" />
    </inertial>
    <visual>
      <origin
        xyz="0 0 0"
        rpy="0 0 0" />
      <geometry>
        <mesh
          filename="package://drchubo_v2/meshes/Body_Torso.STL" />
      </geometry>
      <material
        name="">
        <color
          rgba="0.752941176470588 0.752941176470588 0.752941176470588 1" />
      </material>
    </visual>
    <collision>
      <origin
        xyz="0 0 0"
        rpy="0 0 0" />
      <geometry>
        <mesh
          filename="package://drchubo_v2/meshes/Body_Torso.STL" />
      </geometry>
    </collision>
  </link>
  <link
    name="Body_LSP">
    <inertial>
      <origin
        xyz="0.0125095477277756 0.0682567187642331 -0.000101296692959801"
        rpy="0 0 0" />
      <mass
        value="0.512814669817052" />
      <inertia
        ixx="0.00105971934903801"
        ixy="0.000159674623034314"
        ixz="-8.62192186714616E-07"
        iyy="0.00101602821932241"
        iyz="6.2966884306785E-06"
        izz="0.00161449029531154" />
    </inertial>
    <visual>
      <origin
        xyz="0 0 0"
        rpy="0 0 0" />
      <geometry>
        <mesh
          filename="package://drchubo_v2/meshes/Body_LSP.STL" />
      </geometry>
      <material
        name="">
        <color
          rgba="0.752941176470588 0.752941176470588 0.752941176470588 1" />
      </material>
    </visual>
    <collision>
      <origin
        xyz="0 0 0"
        rpy="0 0 0" />
      <geometry>
        <mesh
          filename="package://drchubo_v2/meshes/Body_LSP.STL" />
      </geometry>
    </collision>
  </link>
  <joint
    name="LSP"
    type="continuous">
    <origin
      xyz="0.000999912451921323 0.130499970437915 0.206099990030136"
      rpy="0 0 0" />
    <parent
      link="Body_Torso" />
    <child
      link="Body_LSP" />
    <axis
      xyz="0 -1 0" />
  </joint>
  <link
    name="Body_LSR">
    <inertial>
      <origin
        xyz="-0.0353989625513559 -0.000442459951967733 -0.0177626332998561"
        rpy="0 0 0" />
      <mass
        value="0.478101234588499" />
      <inertia
        ixx="0.000470991608414918"
        ixy="-9.0901553039533E-08"
        ixz="-1.21957572289795E-05"
        iyy="0.00056865982747998"
        iyz="7.94197935321249E-06"
        izz="0.000377112142444654" />
    </inertial>
    <visual>
      <origin
        xyz="0 0 0"
        rpy="0 0 0" />
      <geometry>
        <mesh
          filename="package://drchubo_v2/meshes/Body_LSR.STL" />
      </geometry>
      <material
        name="">
        <color
          rgba="0.752941176470588 0.752941176470588 0.752941176470588 1" />
      </material>
    </visual>
    <collision>
      <origin
        xyz="0 0 0"
        rpy="0 0 0" />
      <geometry>
        <mesh
          filename="package://drchubo_v2/meshes/Body_LSR.STL" />
      </geometry>
    </collision>
  </link>
  <joint
    name="LSR"
    type="continuous">
    <origin
      xyz="0.0330000045620845 0.099000025 0"
      rpy="0 0 0" />
    <parent
      link="Body_LSP" />
    <child
      link="Body_LSR" />
    <axis
      xyz="-1 0 0" />
  </joint>
  <link
    name="Body_LSY">
    <inertial>
      <origin
        xyz="0.00596307108671425 -0.00223165835990308 -0.16200994741112"
        rpy="0 0 0" />
      <mass
        value="1.35206539449553" />
      <inertia
        ixx="0.0134777313253687"
        ixy="-2.51384514257897E-05"
        ixz="-0.000850780329961022"
        iyy="0.0134238053664017"
        iyz="0.000270964573540381"
        izz="0.00109460289061941" />
    </inertial>
    <visual>
      <origin
        xyz="0 0 0"
        rpy="0 0 0" />
      <geometry>
        <mesh
          filename="package://drchubo_v2/meshes/Body_LSY.STL" />
      </geometry>
      <material
        name="">
        <color
          rgba="0.752941176470588 0.752941176470588 0.752941176470588 1" />
      </material>
    </visual>
    <collision>
      <origin
        xyz="0 0 0"
        rpy="0 0 0" />
      <geometry>
        <mesh
          filename="package://drchubo_v2/meshes/Body_LSY.STL" />
      </geometry>
    </collision>
  </link>
  <joint
    name="LSY"
    type="continuous">
    <origin
      xyz="-0.0330051372049188 0 -0.0269999999999999"
      rpy="0 0 0" />
    <parent
      link="Body_LSR" />
    <child
      link="Body_LSY" />
    <axis
      xyz="0 0 -1" />
  </joint>
  <link
    name="Body_LEP">
    <inertial>
      <origin
        xyz="-0.02571445335908 0.000806178520288664 -0.0417853587164666"
        rpy="0 0 0" />
      <mass
        value="0.267758871202315" />
      <inertia
        ixx="0.000341774590608957"
        ixy="-8.94704764293737E-07"
        ixz="5.48147249702E-05"
        iyy="0.000322402837807457"
        iyz="2.93006728475972E-06"
        izz="0.000239480055722266" />
    </inertial>
    <visual>
      <origin
        xyz="0 0 0"
        rpy="0 0 0" />
      <geometry>
        <mesh
          filename="package://drchubo_v2/meshes/Body_LEP.STL" />
      </geometry>
      <material
        name="">
        <color
          rgba="0.752941176470588 0.752941176470588 0.752941176470588 1" />
      </material>
    </visual>
    <collision>
      <origin
        xyz="0 0 0"
        rpy="0 0 0" />
      <geometry>
        <mesh
          filename="package://drchubo_v2/meshes/Body_LEP.STL" />
      </geometry>
    </collision>
  </link>
  <joint
    name="LEP"
    type="continuous">
    <origin
      xyz="0.0299938548310715 0 -0.273000000000001"
      rpy="0 0 0" />
    <parent
      link="Body_LSY" />
    <child
      link="Body_LEP" />
    <axis
      xyz="0 -1 0" />
  </joint>
  <link
    name="Body_LWY">
    <inertial>
      <origin
        xyz="3.99379011692602E-05 0.0577379856357585 -0.151718765023044"
        rpy="0 0 0" />
      <mass
        value="1.37072161761866" />
      <inertia
        ixx="0.0138917492745533"
        ixy="-3.54251778004189E-06"
        ixz="7.9309444806889E-06"
        iyy="0.0118173705529259"
        iyz="-0.00394273246628464"
        izz="0.00267824831844074" />
    </inertial>
    <visual>
      <origin
        xyz="0 0 0"
        rpy="0 0 0" />
      <geometry>
        <mesh
          filename="package://drchubo_v2/meshes/Body_LWY.STL" />
      </geometry>
      <material
        name="">
        <color
          rgba="0.752941176470588 0.752941176470588 0.752941176470588 1" />
      </material>
    </visual>
    <collision>
      <origin
        xyz="0 0 0"
        rpy="0 0 0" />
      <geometry>
        <mesh
          filename="package://drchubo_v2/meshes/Body_LWY.STL" />
      </geometry>
    </collision>
  </link>
  <joint
    name="LWY"
    type="continuous">
    <origin
      xyz="-0.0300000000000104 0 -0.0520000000000026"
      rpy="0 0 0" />
    <parent
      link="Body_LEP" />
    <child
      link="Body_LWY" />
    <axis
      xyz="0 0 -1" />
  </joint>
  <link
    name="Body_LWP">
    <inertial>
      <origin
        xyz="-0.000378739071217597 0.0108882434913045 0.0170093706107317"
        rpy="0 0 0" />
      <mass
        value="0.294902574333316" />
      <inertia
        ixx="0.000715165417977553"
        ixy="-1.51543969240671E-06"
        ixz="-4.37551165446012E-06"
        iyy="0.000574579884042658"
        iyz="-5.5583549065965E-05"
        izz="0.000301632100473859" />
    </inertial>
    <visual>
      <origin
        xyz="0 0 0"
        rpy="0 0 0" />
      <geometry>
        <mesh
          filename="package://drchubo_v2/meshes/Body_LWP.STL" />
      </geometry>
      <material
        name="">
        <color
          rgba="0.752941176470588 0.752941176470588 0.752941176470588 1" />
      </material>
    </visual>
    <collision>
      <origin
        xyz="0 0 0"
        rpy="0 0 0" />
      <geometry>
        <mesh
          filename="package://drchubo_v2/meshes/Body_LWP.STL" />
      </geometry>
    </collision>
  </link>
  <joint
    name="LWP"
    type="continuous">
    <origin
      xyz="0 0 -0.261789998978664"
      rpy="0 0 0" />
    <parent
      link="Body_LWY" />
    <child
      link="Body_LWP" />
    <axis
      xyz="0 -1 0" />
  </joint>
  <link
    name="Body_LWR">
    <inertial>
      <origin
        xyz="0.00526734472242982 -0.00165481505247564 -0.0476967183846567"
        rpy="0 0 0" />
      <mass
        value="0.474006924726537" />
      <inertia
        ixx="0.000397832341494148"
        ixy="2.62847439473878E-06"
        ixz="-1.84132721696329E-05"
        iyy="0.000310585574870465"
        iyz="-5.74611340451118E-06"
        izz="0.000251799615334244" />
    </inertial>
    <visual>
      <origin
        xyz="0 0 0"
        rpy="0 0 0" />
      <geometry>
        <mesh
          filename="package://drchubo_v2/meshes/Body_LWR.STL" />
      </geometry>
      <material
        name="">
        <color
          rgba="0.752941176470588 0.752941176470588 0.752941176470588 1" />
      </material>
    </visual>
    <collision>
      <origin
        xyz="0 0 0"
        rpy="0 0 0" />
      <geometry>
        <mesh
          filename="package://drchubo_v2/meshes/Body_LWR.STL" />
      </geometry>
    </collision>
  </link>
  <joint
    name="LWR"
    type="continuous">
    <origin
      xyz="0 0 -0.027500000000001"
      rpy="0 0 0" />
    <parent
      link="Body_LWP" />
    <child
      link="Body_LWR" />
    <axis
      xyz="0 0 -1" />
  </joint>
  <link
    name="Body_LF11">
    <inertial>
      <origin
        xyz="4.08082421144568E-06 -0.0103654579068141 -0.0223572146583746"
        rpy="0 0 0" />
      <mass
        value="0.0209635645691505" />
      <inertia
        ixx="5.79877083007342E-06"
        ixy="-3.61896654972963E-09"
        ixz="2.45166522675331E-07"
        iyy="6.02432212425641E-06"
        iyz="1.21167394757334E-09"
        izz="1.78245355770108E-06" />
    </inertial>
    <visual>
      <origin
        xyz="0 0 0"
        rpy="0 0 0" />
      <geometry>
        <mesh
          filename="package://drchubo_v2/meshes/Body_LF1.STL" />
      </geometry>
      <material
        name="">
        <color
          rgba="0.752941176470588 0.752941176470588 0.752941176470588 1" />
      </material>
    </visual>
    <collision>
      <origin
        xyz="0 0 0"
        rpy="0 0 0" />
      <geometry>
        <mesh
          filename="package://drchubo_v2/meshes/Body_LF1.STL" />
      </geometry>
    </collision>
  </link>
  <joint
    name="LF11"
    type="continuous">
    <origin
      xyz="0.0229999999999989 -0.0119703577277603 -0.0754999989786649"
      rpy="0 0 0" />
    <parent
      link="Body_LWR" />
    <child
      link="Body_LF11" />
    <axis
      xyz="0 -1 0" />
  </joint>
  <link
    name="Body_LF12">
    <inertial>
      <origin
        xyz="0.000130946971760824 0.000226771833385403 -0.0135375370531412"
        rpy="0 0 0" />
      <mass
        value="0.0121177256078384" />
      <inertia
        ixx="2.50372945957958E-06"
        ixy="-2.32805891508231E-09"
        ixz="5.14105106916585E-08"
        iyy="2.26813369660349E-06"
        iyz="-4.92964124837522E-09"
        izz="1.22101156825522E-06" />
    </inertial>
    <visual>
      <origin
        xyz="0 0 0"
        rpy="0 0 0" />
      <geometry>
        <mesh
          filename="package://drchubo_v2/meshes/Body_LF2.STL" />
      </geometry>
      <material
        name="">
        <color
          rgba="0.752941176470588 0.752941176470588 0.752941176470588 1" />
      </material>
    </visual>
    <collision>
      <origin
        xyz="0 0 0"
        rpy="0 0 0" />
      <geometry>
        <mesh
          filename="package://drchubo_v2/meshes/Body_LF2.STL" />
      </geometry>
    </collision>
  </link>
  <joint
    name="LF12"
    type="continuous">
    <origin
      xyz="-0.00199999999999857 -0.0105296422722394 -0.0419523539268061"
      rpy="0 0 0" />
    <parent
      link="Body_LF11" />
    <child
      link="Body_LF12" />
    <axis
      xyz="0 1 0" />
  </joint>
  <link
    name="Body_LF13">
    <inertial>
      <origin
        xyz="0.000169386130301579 0.000356898419659246 -0.0163165219752076"
        rpy="0 0 0" />
      <mass
        value="0.0163435127658012" />
      <inertia
        ixx="2.35338373719888E-06"
        ixy="-4.4210418009567E-09"
        ixz="1.38024261681812E-07"
        iyy="2.40973096927305E-06"
        iyz="-2.82215020077362E-08"
        izz="9.69758896639509E-07" />
    </inertial>
    <visual>
      <origin
        xyz="0 0 0"
        rpy="0 0 0" />
      <geometry>
        <mesh
          filename="package://drchubo_v2/meshes/Body_LF3.STL" />
      </geometry>
      <material
        name="">
        <color
          rgba="0.752941176470588 0.752941176470588 0.752941176470588 1" />
      </material>
    </visual>
    <collision>
      <origin
        xyz="0 0 0"
        rpy="0 0 0" />
      <geometry>
        <mesh
          filename="package://drchubo_v2/meshes/Body_LF3.STL" />
      </geometry>
    </collision>
  </link>
  <joint
    name="LF13"
    type="continuous">
    <origin
      xyz="-0.00139999999999867 0 -0.0299673155287558"
      rpy="0 0 0" />
    <parent
      link="Body_LF12" />
    <child
      link="Body_LF13" />
    <axis
      xyz="0 1 0" />
  </joint>
  <link
    name="Body_TSY">
    <inertial>
      <origin
        xyz="-0.0160702033923426 -0.00217130156788575 -0.0329438544914258"
        rpy="0 0 0" />
      <mass
        value="3.85811444190788" />
      <inertia
        ixx="0.0199734074242983"
        ixy="-0.00013227939476964"
        ixz="0.00017668619158262"
        iyy="0.0085778641786012"
        iyz="0.000147644598532384"
        izz="0.0237690845804838" />
    </inertial>
    <visual>
      <origin
        xyz="0 0 0"
        rpy="0 0 0" />
      <geometry>
        <mesh
          filename="package://drchubo_v2/meshes/Body_TSY.STL" />
      </geometry>
      <material
        name="">
        <color
          rgba="0.752941176470588 0.752941176470588 0.752941176470588 1" />
      </material>
    </visual>
    <collision>
      <origin
        xyz="0 0 0"
        rpy="0 0 0" />
      <geometry>
        <mesh
          filename="package://drchubo_v2/meshes/Body_TSY.STL" />
      </geometry>
    </collision>
  </link>
  <joint
    name="TSY"
    type="continuous">
    <origin
      xyz="0 0 0"
      rpy="0 0 0" />
    <parent
      link="Body_Torso" />
    <child
      link="Body_TSY" />
    <axis
      xyz="0 0 -1" />
  </joint>
  <link
    name="Body_LHY">
    <inertial>
      <origin
        xyz="0.0378123600719454 2.54097696217315E-08 -0.116128242308007"
        rpy="0 0 0" />
      <mass
        value="1.02665437743596" />
      <inertia
        ixx="0.00249606232939035"
        ixy="-2.76272075666202E-09"
        ixz="-0.000829704581049298"
        iyy="0.00377324783994803"
        iyz="5.79132768620233E-10"
        izz="0.0021281978106318" />
    </inertial>
    <visual>
      <origin
        xyz="0 0 0"
        rpy="0 0 0" />
      <geometry>
        <mesh
          filename="package://drchubo_v2/meshes/Body_LHY.STL" />
      </geometry>
      <material
        name="">
        <color
          rgba="0.752941176470588 0.752941176470588 0.752941176470588 1" />
      </material>
    </visual>
    <collision>
      <origin
        xyz="0 0 0"
        rpy="0 0 0" />
      <geometry>
        <mesh
          filename="package://drchubo_v2/meshes/Body_LHY.STL" />
      </geometry>
    </collision>
  </link>
  <joint
    name="LHY"
    type="continuous">
    <origin
      xyz="0 0.0884999999998751 -0.0230012618127586"
      rpy="0 0 0" />
    <parent
      link="Body_TSY" />
    <child
      link="Body_LHY" />
    <axis
      xyz="0 0 -1" />
  </joint>
  <link
    name="Body_LHR">
    <inertial>
      <origin
        xyz="0.00473723996484245 -0.00482931760302879 -0.0325563692830159"
        rpy="0 0 0" />
      <mass
        value="1.37473370900606" />
      <inertia
        ixx="0.00222021321390697"
        ixy="3.01344959315266E-05"
        ixz="0.000214745489876361"
        iyy="0.00208177057868792"
        iyz="6.99363261903671E-05"
        izz="0.00174245289623185" />
    </inertial>
    <visual>
      <origin
        xyz="0 0 0"
        rpy="0 0 0" />
      <geometry>
        <mesh
          filename="package://drchubo_v2/meshes/Body_LHR.STL" />
      </geometry>
      <material
        name="">
        <color
          rgba="0.752941176470588 0.752941176470588 0.752941176470588 1" />
      </material>
    </visual>
    <collision>
      <origin
        xyz="0 0 0"
        rpy="0 0 0" />
      <geometry>
        <mesh
          filename="package://drchubo_v2/meshes/Body_LHR.STL" />
      </geometry>
    </collision>
  </link>
  <joint
    name="LHR"
    type="continuous">
    <origin
      xyz="0 0 -0.140984106759769"
      rpy="0 0 0" />
    <parent
      link="Body_LHY" />
    <child
      link="Body_LHR" />
    <axis
      xyz="-1 0 0" />
  </joint>
  <link
    name="Body_LHP">
    <inertial>
      <origin
        xyz="0.0139820973756429 0.0119128547059099 -0.190050892707924"
        rpy="0 0 0" />
      <mass
        value="3.39708806380558" />
      <inertia
        ixx="0.0610144402594715"
        ixy="-0.000679183163268319"
        ixz="-0.00115726366946058"
        iyy="0.0588960128286437"
        iyz="0.00381190200425667"
        izz="0.00864106131257887" />
    </inertial>
    <visual>
      <origin
        xyz="0 0 0"
        rpy="0 0 0" />
      <geometry>
        <mesh
          filename="package://drchubo_v2/meshes/Body_LHP.STL" />
      </geometry>
      <material
        name="">
        <color
          rgba="0.752941176470588 0.752941176470588 0.752941176470588 1" />
      </material>
    </visual>
    <collision>
      <origin
        xyz="0 0 0"
        rpy="0 0 0" />
      <geometry>
        <mesh
          filename="package://drchubo_v2/meshes/Body_LHP.STL" />
      </geometry>
    </collision>
  </link>
  <joint
    name="LHP"
    type="continuous">
    <origin
      xyz="0 0 0"
      rpy="0 0 0" />
    <parent
      link="Body_LHR" />
    <child
      link="Body_LHP" />
    <axis
      xyz="0 -1 0" />
  </joint>
  <link
    name="Body_LKP">
    <inertial>
      <origin
        xyz="0.0167128425968244 -0.00423174064898188 -0.163547981620547"
        rpy="0 0 0" />
      <mass
        value="1.2513314922159" />
      <inertia
        ixx="0.0176853262863822"
        ixy="5.97588040758602E-05"
        ixz="0.000242087956452148"
        iyy="0.0161941871476601"
        iyz="2.05953671058067E-05"
        izz="0.00355046513294474" />
    </inertial>
    <visual>
      <origin
        xyz="0 0 0"
        rpy="0 0 0" />
      <geometry>
        <mesh
          filename="package://drchubo_v2/meshes/Body_LKP.STL" />
      </geometry>
      <material
        name="">
        <color
          rgba="0.752941176470588 0.752941176470588 0.752941176470588 1" />
      </material>
    </visual>
    <collision>
      <origin
        xyz="0 0 0"
        rpy="0 0 0" />
      <geometry>
        <mesh
          filename="package://drchubo_v2/meshes/Body_LKP.STL" />
      </geometry>
    </collision>
  </link>
  <joint
    name="LKP"
    type="continuous">
    <origin
      xyz="0 0 -0.329885000000079"
      rpy="0 0 0" />
    <parent
      link="Body_LHP" />
    <child
      link="Body_LKP" />
    <axis
      xyz="0 -1 0" />
  </joint>
  <link
    name="Body_LAP">
    <inertial>
      <origin
        xyz="0.0148223972690647 0.0100562738748088 0.00997467775305361"
        rpy="0 0 0" />
      <mass
        value="2.00597218062827" />
      <inertia
        ixx="0.00317573590934402"
        ixy="-0.00030397733226894"
        ixz="-0.000298327569678596"
        iyy="0.00347243568780368"
        iyz="-0.000320093631728957"
        izz="0.0036796574607068" />
    </inertial>
    <visual>
      <origin
        xyz="0 0 0"
        rpy="0 0 0" />
      <geometry>
        <mesh
          filename="package://drchubo_v2/meshes/Body_LAP.STL" />
      </geometry>
      <material
        name="">
        <color
          rgba="0.752941176470588 0.752941176470588 0.752941176470588 1" />
      </material>
    </visual>
    <collision>
      <origin
        xyz="0 0 0"
        rpy="0 0 0" />
      <geometry>
        <mesh
          filename="package://drchubo_v2/meshes/Body_LAP.STL" />
      </geometry>
    </collision>
  </link>
  <joint
    name="LAP"
    type="continuous">
    <origin
      xyz="0 0 -0.330014445029992"
      rpy="0 0 0" />
    <parent
      link="Body_LKP" />
    <child
      link="Body_LAP" />
    <axis
      xyz="0 -1 0" />
  </joint>
  <link
    name="Body_LAR">
    <inertial>
      <origin
        xyz="0.0165455008793805 0.00216085982209592 -0.0952915062130097"
        rpy="0 0 0" />
      <mass
        value="1.06815376654094" />
      <inertia
        ixx="0.00372790935829238"
        ixy="3.13391462968031E-05"
        ixz="-0.000480888102685697"
        iyy="0.00607005664613535"
        iyz="-9.42514897869005E-05"
        izz="0.00420512438203011" />
    </inertial>
    <visual>
      <origin
        xyz="0 0 0"
        rpy="0 0 0" />
      <geometry>
        <mesh
          filename="package://drchubo_v2/meshes/Body_LAR.STL" />
      </geometry>
      <material
        name="">
        <color
          rgba="0.752941176470588 0.752941176470588 0.752941176470588 1" />
      </material>
    </visual>
    <collision>
      <origin
        xyz="0 0 0"
        rpy="0 0 0" />
      <geometry>
        <mesh
          filename="package://drchubo_v2/meshes/Body_LAR.STL" />
      </geometry>
    </collision>
  </link>
  <joint
    name="LAR"
    type="continuous">
    <origin
      xyz="0 0 0"
      rpy="0 0 0" />
    <parent
      link="Body_LAP" />
    <child
      link="Body_LAR" />
    <axis
      xyz="-1 0 0" />
  </joint>
  <link
    name="Body_NKY">
    <inertial>
      <origin
        xyz="-0.0132341759354885 -0.000264833073564218 0.0409690989083223"
        rpy="0 0 0" />
      <mass
        value="0.170508153365938" />
      <inertia
        ixx="0.000101054047458944"
        ixy="-6.00968902822632E-07"
        ixz="-2.18923858832909E-06"
        iyy="0.000105642534003898"
        iyz="5.06882999846784E-07"
        izz="0.000105863654255542" />
    </inertial>
    <visual>
      <origin
        xyz="0 0 0"
        rpy="0 0 0" />
      <geometry>
        <mesh
          filename="package://drchubo_v2/meshes/Body_NKY.STL" />
      </geometry>
      <material
        name="">
        <color
          rgba="0.752941176470588 0.752941176470588 0.752941176470588 1" />
      </material>
    </visual>
    <collision>
      <origin
        xyz="0 0 0"
        rpy="0 0 0" />
      <geometry>
        <mesh
          filename="package://drchubo_v2/meshes/Body_NKY.STL" />
      </geometry>
    </collision>
  </link>
  <joint
    name="NKY"
    type="continuous">
    <origin
      xyz="0.000999912928068312 -1.0274409856648E-05 0.25979999003014"
      rpy="0 0 0" />
    <parent
      link="Body_Torso" />
    <child
      link="Body_NKY" />
    <axis
      xyz="0 0 -1" />
  </joint>
  <link
    name="Body_NK1">
    <inertial>
      <origin
        xyz="-0.000519835312274866 -0.112505098178575 -9.33147645172232E-05"
        rpy="0 0 0" />
      <mass
        value="0.657803087875364" />
      <inertia
        ixx="0.00461193404989021"
        ixy="2.06037288507875E-05"
        ixz="-3.18942823947151E-08"
        iyy="0.00189695830911958"
        iyz="8.9775768045783E-05"
        izz="0.00293465680409193" />
    </inertial>
    <visual>
      <origin
        xyz="0 0 0"
        rpy="0 0 0" />
      <geometry>
        <mesh
          filename="package://drchubo_v2/meshes/Body_NK1.STL" />
      </geometry>
      <material
        name="">
        <color
          rgba="0.752941176470588 0.752941176470588 0.752941176470588 1" />
      </material>
    </visual>
    <collision>
      <origin
        xyz="0 0 0"
        rpy="0 0 0" />
      <geometry>
        <mesh
          filename="package://drchubo_v2/meshes/Body_NK1.STL" />
      </geometry>
    </collision>
  </link>
  <joint
    name="NK1"
    type="continuous">
    <origin
      xyz="0 0 0.0297999999999999"
      rpy="-1.5707963267949 0 0" />
    <parent
      link="Body_NKY" />
    <child
      link="Body_NK1" />
    <axis
      xyz="0 0 -1" />
  </joint>
  <link
    name="Body_NK2">
    <inertial>
      <origin
        xyz="0.00619110883708962 0.000180362999792852 -0.00925441765145953"
        rpy="0 0 0" />
      <mass
        value="0.250303289297233" />
      <inertia
        ixx="0.000202848165255698"
        ixy="-2.85613884397634E-07"
        ixz="4.4023872954844E-06"
        iyy="0.000189595993252901"
        iyz="4.2100514679016E-07"
        izz="0.000145991865917545" />
    </inertial>
    <visual>
      <origin
        xyz="0 0 0"
        rpy="0 0 0" />
      <geometry>
        <mesh
          filename="package://drchubo_v2/meshes/Body_NK2.STL" />
      </geometry>
      <material
        name="">
        <color
          rgba="0.752941176470588 0.752941176470588 0.752941176470588 1" />
      </material>
    </visual>
    <collision>
      <origin
        xyz="0 0 0"
        rpy="0 0 0" />
      <geometry>
        <mesh
          filename="package://drchubo_v2/meshes/Body_NK2.STL" />
      </geometry>
    </collision>
  </link>
  <joint
    name="NK2"
    type="continuous">
    <origin
      xyz="0 -0.0859999999999995 0"
      rpy="1.5707963267949 -6.11557787917604E-17 -1.5707963267949" />
    <parent
      link="Body_NK1" />
    <child
      link="Body_NK2" />
    <axis
      xyz="0 -1 0" />
  </joint>

  <link
    name="Body_LF21">
    <inertial>
      <origin
        xyz="4.08082421144568E-06 -0.0103654579068141 -0.0223572146583746"
        rpy="0 0 0" />
      <mass
        value="0.0209635645691505" />
      <inertia
        ixx="5.79877083007342E-06"
        ixy="-3.61896654972963E-09"
        ixz="2.45166522675331E-07"
        iyy="6.02432212425641E-06"
        iyz="1.21167394757334E-09"
        izz="1.78245355770108E-06" />
    </inertial>
    <visual>
      <origin
        xyz="0 0 0"
        rpy="0 0 0" />
      <geometry>
        <mesh
          filename="package://drchubo_v2/meshes/Body_LF1.STL" />
      </geometry>
      <material
        name="">
        <color
          rgba="0.752941176470588 0.752941176470588 0.752941176470588 1" />
      </material>
    </visual>
    <collision>
      <origin
        xyz="0 0 0"
        rpy="0 0 0" />
      <geometry>
        <mesh
          filename="package://drchubo_v2/meshes/Body_LF1.STL" />
      </geometry>
    </collision>
  </link>
  <joint
    name="LF21"
    type="continuous">
    <origin
      xyz="0.0229999999999989 0.033 -0.0754999989786649"
      rpy="0 0 0" />
    <parent
      link="Body_LWR" />
    <child
      link="Body_LF21" />
    <axis
      xyz="0 -1 0" />
  </joint>
  <link
    name="Body_LF22">
    <inertial>
      <origin
        xyz="0.000130946971760824 0.000226771833385403 -0.0135375370531412"
        rpy="0 0 0" />
      <mass
        value="0.0121177256078384" />
      <inertia
        ixx="2.50372945957958E-06"
        ixy="-2.32805891508231E-09"
        ixz="5.14105106916585E-08"
        iyy="2.26813369660349E-06"
        iyz="-4.92964124837522E-09"
        izz="1.22101156825522E-06" />
    </inertial>
    <visual>
      <origin
        xyz="0 0 0"
        rpy="0 0 0" />
      <geometry>
        <mesh
          filename="package://drchubo_v2/meshes/Body_LF2.STL" />
      </geometry>
      <material
        name="">
        <color
          rgba="0.752941176470588 0.752941176470588 0.752941176470588 1" />
      </material>
    </visual>
    <collision>
      <origin
        xyz="0 0 0"
        rpy="0 0 0" />
      <geometry>
        <mesh
          filename="package://drchubo_v2/meshes/Body_LF2.STL" />
      </geometry>
    </collision>
  </link>
  <joint
    name="LF22"
    type="continuous">
    <origin
      xyz="-0.00199999999999857 -0.0105296422722394 -0.0419523539268061"
      rpy="0 0 0" />
    <parent
      link="Body_LF21" />
    <child
      link="Body_LF22" />
    <axis
      xyz="0 1 0" />
  </joint>
  <link
    name="Body_LF23">
    <inertial>
      <origin
        xyz="0.000169386130301579 0.000356898419659246 -0.0163165219752076"
        rpy="0 0 0" />
      <mass
        value="0.0163435127658012" />
      <inertia
        ixx="2.35338373719888E-06"
        ixy="-4.4210418009567E-09"
        ixz="1.38024261681812E-07"
        iyy="2.40973096927305E-06"
        iyz="-2.82215020077362E-08"
        izz="9.69758896639509E-07" />
    </inertial>
    <visual>
      <origin
        xyz="0 0 0"
        rpy="0 0 0" />
      <geometry>
        <mesh
          filename="package://drchubo_v2/meshes/Body_LF3.STL" />
      </geometry>
      <material
        name="">
        <color
          rgba="0.752941176470588 0.752941176470588 0.752941176470588 1" />
      </material>
    </visual>
    <collision>
      <origin
        xyz="0 0 0"
        rpy="0 0 0" />
      <geometry>
        <mesh
          filename="package://drchubo_v2/meshes/Body_LF3.STL" />
      </geometry>
    </collision>
  </link>
  <joint
    name="LF23"
    type="continuous">
    <origin
      xyz="-0.00139999999999867 0 -0.0299673155287558"
      rpy="0 0 0" />
    <parent
      link="Body_LF22" />
    <child
      link="Body_LF23" />
    <axis
      xyz="0 1 0" />
  </joint>

  <!-- thumb-->
  <link
    name="Body_LF31">
    <inertial>
      <origin
        xyz="4.08082421144568E-06 -0.0103654579068141 -0.0223572146583746"
        rpy="0 0 0" />
      <mass
        value="0.0209635645691505" />
      <inertia
        ixx="5.79877083007342E-06"
        ixy="-3.61896654972963E-09"
        ixz="2.45166522675331E-07"
        iyy="6.02432212425641E-06"
        iyz="1.21167394757334E-09"
        izz="1.78245355770108E-06" />
    </inertial>
    <visual>
      <origin
        xyz="0 0 0"
        rpy="0 0 0" />
      <geometry>
        <mesh
          filename="package://drchubo_v2/meshes/Body_LF1.STL" />
      </geometry>
      <material
        name="">
        <color
          rgba="0.752941176470588 0.752941176470588 0.752941176470588 1" />
      </material>
    </visual>
    <collision>
      <origin
        xyz="0 0 0"
        rpy="0 0 0" />
      <geometry>
        <mesh
          filename="package://drchubo_v2/meshes/Body_LF1.STL" />
      </geometry>
    </collision>
  </link>
  <joint
    name="LF31"
    type="continuous">
    <origin
      xyz="-0.023 -0.0105 -0.0754999989786649"
      rpy="0 0 3.141592653589" />
    <parent
      link="Body_LWR" />
    <child
      link="Body_LF31" />
    <axis
      xyz="0 -1 0" />
  </joint>
  <link
    name="Body_LF32">
    <inertial>
      <origin
        xyz="0.000130946971760824 0.000226771833385403 -0.0135375370531412"
        rpy="0 0 0" />
      <mass
        value="0.0121177256078384" />
      <inertia
        ixx="2.50372945957958E-06"
        ixy="-2.32805891508231E-09"
        ixz="5.14105106916585E-08"
        iyy="2.26813369660349E-06"
        iyz="-4.92964124837522E-09"
        izz="1.22101156825522E-06" />
    </inertial>
    <visual>
      <origin
        xyz="0 0 0"
        rpy="0 0 0" />
      <geometry>
        <mesh
          filename="package://drchubo_v2/meshes/Body_LF2.STL" />
      </geometry>
      <material
        name="">
        <color
          rgba="0.752941176470588 0.752941176470588 0.752941176470588 1" />
      </material>
    </visual>
    <collision>
      <origin
        xyz="0 0 0"
        rpy="0 0 0" />
      <geometry>
        <mesh
          filename="package://drchubo_v2/meshes/Body_LF2.STL" />
      </geometry>
    </collision>
  </link>
  <joint
    name="LF32"
    type="continuous">
    <origin
      xyz="-0.00199999999999857 -0.0105296422722394 -0.0419523539268061"
      rpy="0 0 0" />
    <parent
      link="Body_LF31" />
    <child
      link="Body_LF32" />
    <axis
      xyz="0 1 0" />
  </joint>
  <link
    name="Body_LF33">
    <inertial>
      <origin
        xyz="0.000169386130301579 0.000356898419659246 -0.0163165219752076"
        rpy="0 0 0" />
      <mass
        value="0.0163435127658012" />
      <inertia
        ixx="2.35338373719888E-06"
        ixy="-4.4210418009567E-09"
        ixz="1.38024261681812E-07"
        iyy="2.40973096927305E-06"
        iyz="-2.82215020077362E-08"
        izz="9.69758896639509E-07" />
    </inertial>
    <visual>
      <origin
        xyz="0 0 0"
        rpy="0 0 0" />
      <geometry>
        <mesh
          filename="package://drchubo_v2/meshes/Body_LF3.STL" />
      </geometry>
      <material
        name="">
        <color
          rgba="0.752941176470588 0.752941176470588 0.752941176470588 1" />
      </material>
    </visual>
    <collision>
      <origin
        xyz="0 0 0"
        rpy="0 0 0" />
      <geometry>
        <mesh
          filename="package://drchubo_v2/meshes/Body_LF3.STL" />
      </geometry>
    </collision>
  </link>
  <joint
    name="LF33"
    type="continuous">
    <origin
      xyz="-0.00139999999999867 0 -0.0299673155287558"
      rpy="0 0 0" />
    <parent
      link="Body_LF32" />
    <child
      link="Body_LF33" />
    <axis
      xyz="0 1 0" />
  </joint>
</robot>
